Workbook

Sheet Dashboard
A1: PROCUREMENT SPEND ANALYSIS DASHBOARD
A2: Sample portfolio project • Synthetic data • 2025
A4: Total Spend (USD) | B4: =SUM(Clean_Data!L:L) | C4: Transactions | D4: =COUNTA(Clean_Data!A:A)-1 | E4: Suppliers (unique names) | F4: =SUMPRODUCT((Clean_Data!N2:N601<>"")/COUNTIF(Clean_Data!N2:N601,Clean_Data!N2:N601&"")) | G4: Records to Review | H4: =COUNTIF(Clean_Data!P:P,"Check Missing/Invalid Data")
A22: How to use
A23: 1. Review Raw_Data and Clean_Data. 2. Inspect Supplier_Review for normalized supplier names. 3. Use category/month summaries to discuss trends.

Sheet Raw_Data
A1: Transaction_ID | B1: Transaction_Date | C1: Document_Type | D1: Supplier_ID | E1: Supplier_Name | F1: Category | G1: Item_Description | H1: Business_Unit | I1: Region | J1: Quantity | K1: Unit_Price_USD | L1: Spend_USD | M1: Payment_Status
A2: PO-00181 | B2: 45658 | C2: Goods Receipt | D2: SUP010 | E2: Urban Energy Solutions | F2: Utilities | G2: Natural gas | H2: Corporate | I2: East | J2: 24 | K2: 430.14 | L2: 10323.47 | M2: Paid
A3: PO-00580 | B3: 45658 | C3: Purchase Order | D3: SUP011 | E3: Vertex Marketing | F3: Marketing | G3: Promotional materials | H3: Technology | I3: South | J3: 114 | K3: 116.12 | L3: 13237.8 | M3: Pending
A4: PO-00324 | B4: 45659 | C4: Goods Receipt | D4: SUP012 | E4: Pioneer Hardware | F4: Maintenance | G4: Tools and supplies | H4: Technology | I4: North | J4: 82 | K4: 213.44 | L4: 17502.05 | M4: Overdue
A5: PO-00391 | B5: 45659 | C5: Goods Receipt | D5: SUP007 | E5: BrightClean Facilities | F5: Facilities | G5: Facility maintenance | H5: Operations | I5: North | J5: 81 | K5: 183.35 | L5: 14851.28 | M5: Paid
A6: PO-00494 | B6: 45660 | C6: Goods Receipt | D6: SUP006 | E6: Metro Logistics Pvt Ltd | F6: Logistics | G6: Courier services | H6: Technology | I6: East | J6: 95 | K6: 73.03 | L6: 6937.5 | M6: Paid
A7: PO-00271 | B7: 45661 | C7: Goods Receipt | D7: SUP009 | E7: Summit Consulting | F7: Professional Services | G7: Training services | H7: Manufacturing | I7: East | J7: 68 | K7: 8.3 | L7: 564.22 | M7: Paid
A8: PO-00354 | B8: 45661 | C8: Goods Receipt | D8: SUP007 | E8: BrightClean Facilities | F8: Maintenance | G8: Repair parts | H8: Technology | I8: North | J8: 108 | K8: 58.46 | L8: 6314.06 | M8: Overdue
A9: PO-00061 | B9: 45661 | C9: Invoice | D9: SUP006 | E9: Metro Logistics Pvt Ltd | F9: Logistics | G9: Warehouse handling | H9: Manufacturing | I9: South | J9: 115 | K9: 104.85 | L9: 12058.03 | M9: Pending
A10: PO-00506 | B10: 45661 | C10: Purchase Order | D10: SUP009 | E10: Summit Consulting | F10: Professional Services | G10: Audit support | H10: Technology | I10: South | J10: 30 | K10: 452.51 | L10: 13575.16 | M10: Paid
A11: PO-00413 | B11: 45662 | C11: Purchase Order | D11: SUP008 | E11: GreenLeaf Packaging | F11: Packaging | G11: Corrugated boxes | H11: Technology | I11: East | J11: 77 | K11: 151.88 | L11: 11695 | M11: Overdue
A12: PO-00117 | B12: 45662 | C12: Goods Receipt | D12: SUP010 | E12: Urban Energy Solutions | F12: Utilities | G12: Natural gas | H12: Sales | I12: East | J12: 7 | K12: 2005.17 | L12: 14036.21 | M12: Paid
A13: PO-00331 | B13: 45662 | C13: Invoice | D13: SUP012 | E13: Pioneer Hardware | F13: Maintenance | G13: Tools and supplies | H13: Operations | I13: West | J13: 111 | K13: 20.51 | L13: 2276.22 | M13: Paid
... A16: PO-00526 | B16: 45663 | C16: Invoice | D16: SUP004 | E16: North Star IT Svc | F16: IT Services | G16: Software support | H16: Corporate | I16: South | J16: 67 | K16: 425.3 | L16: 28495.33 | M16: Overdue
A17: PO-00561 | B17: 45663 | C17: Invoice | D17: SUP001 | F17: Office Supplies | G17: Pens and stationery | H17: Sales | I17: North | J17: 18 | K17: 759.91 | L17: 13678.29 | M17: Overdue
A18: PO-00349 | B18: 45664 | C18: Purchase Order | D18: SUP004 | E18: North Star IT Svc | F18: Professional Services | G18: Business consulting | H18: Manufacturing | I18: West | J18: 20 | K18: 592.25 | L18: 11845.04 | M18: Paid
A19: PO-00466 | B19: 45664 | C19: Goods Receipt | D19: SUP009 | E19: Summit Consulting | F19: Professional Services | G19: Business consulting | H19: Operations | I19: East | J19: 7 | K19: 1682.99 | L19: 11780.93 | M19: Paid
A20: PO-00100 | B20: 45665 | C20: Purchase Order | D20: SUP009 | E20: Summit Consulting | F20: Professional Services | G20: Training services | H20: Corporate | I20: South | J20: 108 | K20: 65.13 | L20: 7034 | M20: Pending
A21: PO-00077 | B21: 45666 | C21: Invoice | D21: SUP002 | E21: Apex Office Supply Ltd | F21: Office Supplies | G21: Toner cartridges | H21: Manufacturing | I21: East | J21: 32 | K21: 229.71 | L21: 7350.69 | M21: Pending
A22: PO-00593 | B22: 45666 | C22: Invoice | D22: SUP009 | E22: Summit Consulting | F22: Professional Services | G22: Business consulting | H22: Operations | I22: East | J22: 1 | K22: 27266.31 | L22: 27266.31 | M22: Paid
A23: PO-00021 | B23: 45668 | C23: Purchase Order | D23: SUP010 | E23: Urban Energy Solutions | F23: Utilities | G23: Natural gas | H23: Corporate | I23: South | J23: 1 | K23: 10641.31 | L23: 10641.31 | M23: Paid
A24: PO-00419 | B24: 45671 | C24: Invoice | D24: SUP011 | E24: Vertex Marketing | F24: Marketing | G24: Print advertising | H24: Sales | I24: North | J24: 117 | K24: 46.2 | L24: 5405.41 | M24: Overdue
A25: PO-00176 | B25: 45671 | C25: Purchase Order | D25: SUP007 | E25: BrightClean Facilities | F25: Maintenance | G25: Equipment servicing | H25: Operations | I25: North | J25: 50 | K25: 136.13 | L25: 6806.43 | M25: Pending
A26: PO-00022 | B26: 45674 | C26: Invoice | D26: SUP006 | E26: Metro Logistics Pvt Ltd | F26: Logistics | G26: Freight services | H26: Manufacturing | I26: South | J26: 86 | K26: 86.49 | L26: 7438.39 | M26: Overdue
A27: PO-00010 | B27: 45674 | C27: Goods Receipt | D27: SUP006 | E27: Metro Logistics Pvt Ltd | F27: Logistics | G27: Warehouse handling | H27: Technology | I27: South | J27: 117 | K27: 18.94 | L27: 2215.87 | M27: Overdue
A28: PO-00382 | B28: 45674 | C28: Purchase Order | D28: SUP003 | E28: Northstar IT Services | F28: IT Services | G28: IT consulting | H28: Manufacturing | I28: North | J28: 79 | K28: 356.96 | L28: 28199.88 | M28: Pending
A29: PO-00126 | B29: 45677 | C29: Goods Receipt | D29: SUP005 | E29: Metro Logistics | F29: Logistics | G29: Freight services | H29: Sales | I29: West | J29: 31 | K29: 120.44 | L29: 3733.6 | M29: Pending
... A43: PO-00470 | B43: 45685 | C43: Invoice | D43: SUP001 | E43: Apex Office Supplies | F43: Office Supplies | G43: Printer paper | H43: Technology | I43: South | J43: 112 | K43: 33.49 | L43: 3751.2 | M43: Overdue
A44: PO-00389 | B44: 45685 | C44: Goods Receipt | D44: SUP002 | E44: Apex Office Supply Ltd | G44: Toner cartridges | H44: Manufacturing | I44: East | J44: 53 | K44: 330.99 | L44: 17542.24 | M44: Overdue
A45: PO-00598 | B45: 45686 | C45: Purchase Order | D45: SUP006 | E45: Metro Logistics Pvt Ltd | F45: Logistics | G45: Freight services | H45: Manufacturing | I45: North | J45: 54 | K45: 463.74 | L45: 25041.84 | M45: Overdue
A46: PO-00259 | B46: 45687 | C46: Purchase Order | D46: SUP009 | E46: Summit Consulting | F46: Professional Services | G46: Training services | H46: Operations | I46: East | J46: 68 | K46: 189.18 | L46: 12864.17 | M46: Paid
A47: PO-00321 | B47: 45688 | C47: Purchase Order | D47: SUP005 | E47: Metro Logistics | F47: Logistics | G47: Freight services | H47: Operations | I47: East | J47: 111 | K47: 36.58 | L47: 4060.89 | M47: Paid
A48: PO-00581 | B48: 45690 | C48: Goods Receipt | D48: SUP011 | E48: Vertex Marketing | F48: Marketing | G48: Promotional materials | H48: Sales | I48: South | J48: 25 | K48: 590.58 | L48: 14764.61 | M48: Overdue
A49: PO-00125 | B49: 45690 | C49: Goods Receipt | D49: SUP011 | E49: Vertex Marketing | F49: Marketing | G49: Print advertising | H49: Corporate | I49: South | J49: 39 | K49: 420 | L49: 16379.85 | M49: Paid
A50: PO-00480 | B50: 45691 | C50: Goods Receipt | D50: SUP004 | E50: North Star IT Svc | F50: IT Services | G50: Cloud services | H50: Corporate | I50: South | J50: 111 | K50: 213.67 | L50: 23717.81 | M50: Overdue
A51: PO-00048 | B51: 45693 | C51: Purchase Order | D51: SUP011 | E51: Vertex Marketing | F51: Marketing | G51: Promotional materials | H51: Technology | I51: East | J51: 85 | K51: 132.49 | L51: 11262.02 | M51: Overdue
A52: PO-00084 | B52: 45695 | C52: Goods Receipt | D52: SUP010 | E52: Urban Energy Solutions | F52: Utilities | G52: Water services | H52: Corporate | I52: South | J52: 20 | K52: 53.93 | L52: 1078.53 | M52: Paid
A53: PO-00280 | B53: 45698 | C53: Invoice | D53: SUP009 | E53: Summit Consulting | F53: Professional Services | G53: Business consulting | H53: Corporate | I53: East | J53: 13 | K53: 824.37 | L53: 10716.75 | M53: Overdue
A54: PO-00229 | B54: 45698 | C54: Invoice | D54: SUP006 | E54: Metro Logistics Pvt Ltd | F54: Logistics | G54: Freight services | H54: Operations | I54: East | J54: 96 | K54: 209.82 | L54: 20142.93 | M54: Overdue
A55: PO-00552 | B55: 45698 | C55: Invoice | D55: SUP003 | E55: Northstar IT Services | F55: IT Services | G55: IT consulting | H55: Technology | I55: West | J55: 84 | K55: 115.86 | L55: 9732.6 | M55: Pending
...

Sheet Clean_Data
A1: Transaction_ID | B1: Transaction_Date | C1: Document_Type | D1: Supplier_ID | E1: Supplier_Name | F1: Category | G1: Item_Description | H1: Business_Unit | I1: Region | J1: Quantity | K1: Unit_Price_USD | L1: Spend_USD | M1: Payment_Status | N1: Normalized_Supplier | O1: Spend_Valid_Flag | P1: Data_Quality_Flag
A2: PO-00181 | B2: 45658 | C2: Goods Receipt | D2: SUP010 | E2: =IF(E2="","Unknown Supplier",TRIM(E2)) | F2: =IF(F2="","Unclassified",TRIM(F2)) | G2: Natural gas | H2: Corporate | I2: East | J2: 24 | K2: 430.14 | L2: 10323.47 | M2: Paid | N2: =IF(OR(E2="Apex Office Supplies",E2="Apex Office Supply Ltd"),"Apex Office Supplies",IF(OR(E2="Northstar IT Services",E2="North Star IT Svc"),"Northstar IT Services",IF(OR(E2="Metro Logistics",E2="Metro Logistics Pvt Ltd"),"Metro Logistics",E2))) | O2: =IF(AND(ISNUMBER(L2),L2>0),"Valid","Review") | P2: =IF(OR(E2="",F2="",NOT(ISNUMBER(L2))),"Check Missing/Invalid Data","OK")
A3: PO-00580 | B3: 45658 | C3: Purchase Order | D3: SUP011 | E3: =IF(E3="","Unknown Supplier",TRIM(E3)) | F3: =IF(F3="","Unclassified",TRIM(F3)) | G3: Promotional materials | H3: Technology | I3: South | J3: 114 | K3: 116.12 | L3: 13237.8 | M3: Pending | N3: =IF(OR(E3="Apex Office Supplies",E3="Apex Office Supply Ltd"),"Apex Office Supplies",IF(OR(E3="Northstar IT Services",E3="North Star IT Svc"),"Northstar IT Services",IF(OR(E3="Metro Logistics",E3="Metro Logistics Pvt Ltd"),"Metro Logistics",E3))) | O3: =IF(AND(ISNUMBER(L3),L3>0),"Valid","Review") | P3: =IF(OR(E3="",F3="",NOT(ISNUMBER(L3))),"Check Missing/Invalid Data","OK")
A4: PO-00324 | B4: 45659 | C4: Goods Receipt | D4: SUP012 | E4: =IF(E4="","Unknown Supplier",TRIM(E4)) | F4: =IF(F4="","Unclassified",TRIM(F4)) | G4: Tools and supplies | H4: Technology | I4: North | J4: 82 | K4: 213.44 | L4: 17502.05 | M4: Overdue | N4: =IF(OR(E4="Apex Office Supplies",E4="Apex Office Supply Ltd"),"Apex Office Supplies",IF(OR(E4="Northstar IT Services",E4="North Star IT Svc"),"Northstar IT Services",IF(OR(E4="Metro Logistics",E4="Metro Logistics Pvt Ltd"),"Metro Logistics",E4))) | O4: =IF(AND(ISNUMBER(L4),L4>0),"Valid","Review") | P4: =IF(OR(E4="",F4="",NOT(ISNUMBER(L4))),"Check Missing/Invalid Data","OK")
A5: PO-00391 | B5: 45659 | C5: Goods Receipt | D5: SUP007 | E5: =IF(E5="","Unknown Supplier",TRIM(E5)) | F5: =IF(F5="","Unclassified",TRIM(F5)) | G5: Facility maintenance | H5: Operations | I5: North | J5: 81 | K5: 183.35 | L5: 14851.28 | M5: Paid | N5: =IF(OR(E5="Apex Office Supplies",E5="Apex Office Supply Ltd"),"Apex Office Supplies",IF(OR(E5="Northstar IT Services",E5="North Star IT Svc"),"Northstar IT Services",IF(OR(E5="Metro Logistics",E5="Metro Logistics Pvt Ltd"),"Metro Logistics",E5))) | O5: =IF(AND(ISNUMBER(L5),L5>0),"Valid","Review") | P5: =IF(OR(E5="",F5="",NOT(ISNUMBER(L5))),"Check Missing/Invalid Data","OK")
A6: PO-00494 | B6: 45660 | C6: Goods Receipt | D6: SUP006 | E6: =IF(E6="","Unknown Supplier",TRIM(E6)) | F6: =IF(F6="","Unclassified",TRIM(F6)) | G6: Courier services | H6: Technology | I6: East | J6: 95 | K6: 73.03 | L6: 6937.5 | M6: Paid | N6: =IF(OR(E6="Apex Office Supplies",E6="Apex Office Supply Ltd"),"Apex Office Supplies",IF(OR(E6="Northstar IT Services",E6="North Star IT Svc"),"Northstar IT Services",IF(OR(E6="Metro Logistics",E6="Metro Logistics Pvt Ltd"),"Metro Logistics",E6))) | O6: =IF(AND(ISNUMBER(L6),L6>0),"Valid","Review") | P6: =IF(OR(E6="",F6="",NOT(ISNUMBER(L6))),"Check Missing/Invalid Data","OK")
A7: PO-00271 | B7: 45661 | C7: Goods Receipt | D7: SUP009 | E7: =IF(E7="","Unknown Supplier",TRIM(E7)) | F7: =IF(F7="","Unclassified",TRIM(F7)) | G7: Training services | H7: Manufacturing | I7: East | J7: 68 | K7: 8.3 | L7: 564.22 | M7: Paid | N7: =IF(OR(E7="Apex Office Supplies",E7="Apex Office Supply Ltd"),"Apex Office Supplies",IF(OR(E7="Northstar IT Services",E7="North Star IT Svc"),"Northstar IT Services",IF(OR(E7="Metro Logistics",E7="Metro Logistics Pvt Ltd"),"Metro Logistics",E7))) | O7: =IF(AND(ISNUMBER(L7),L7>0),"Valid","Review") | P7: =IF(OR(E7="",F7="",NOT(ISNUMBER(L7))),"Check Missing/Invalid Data","OK")
A8: PO-00354 | B8: 45661 | C8: Goods Receipt | D8: SUP007 | E8: =IF(E8="","Unknown Supplier",TRIM(E8)) | F8: =IF(F8="","Unclassified",TRIM(F8)) | G8: Repair parts | H8: Technology | I8: North | J8: 108 | K8: 58.46 | L8: 6314.06 | M8: Overdue | N8: =IF(OR(E8="Apex Office Supplies",E8="Apex Office Supply Ltd"),"Apex Office Supplies",IF(OR(E8="Northstar IT Services",E8="North Star IT Svc"),"Northstar IT Services",IF(OR(E8="Metro Logistics",E8="Metro Logistics Pvt Ltd"),"Metro Logistics",E8))) | O8: =IF(AND(ISNUMBER(L8),L8>0),"Valid","Review") | P8: =IF(OR(E8="",F8="",NOT(ISNUMBER(L8))),"Check Missing/Invalid Data","OK")
A9: PO-00061 | B9: 45661 | C9: Invoice | D9: SUP006 | E9: =IF(E9="","Unknown Supplier",TRIM(E9)) | F9: =IF(F9="","Unclassified",TRIM(F9)) | G9: Warehouse handling | H9: Manufacturing | I9: South | J9: 115 | K9: 104.85 | L9: 12058.03 | M9: Pending | N9: =IF(OR(E9="Apex Office Supplies",E9="Apex Office Supply Ltd"),"Apex Office Supplies",IF(OR(E9="Northstar IT Services",E9="North Star IT Svc"),"Northstar IT Services",IF(OR(E9="Metro Logistics",E9="Metro Logistics Pvt Ltd"),"Metro Logistics",E9))) | O9: =IF(AND(ISNUMBER(L9),L9>0),"Valid","Review") | P9: =IF(OR(E9="",F9="",NOT(ISNUMBER(L9))),"Check Missing/Invalid Data","OK")
A10: PO-00506 | B10: 45661 | C10: Purchase Order | D10: SUP009 | E10: =IF(E10="","Unknown Supplier",TRIM(E10)) | F10: =IF(F10="","Unclassified",TRIM(F10)) | G10: Audit support | H10: Technology | I10: South | J10: 30 | K10: 452.51 | L10: 13575.16 | M10: Paid | N10: =IF(OR(E10="Apex Office Supplies",E10="Apex Office Supply Ltd"),"Apex Office Supplies",IF(OR(E10="Northstar IT Services",E10="North Star IT Svc"),"Northstar IT Services",IF(OR(E10="Metro Logistics",E10="Metro Logistics Pvt Ltd"),"Metro Logistics",E10))) | O10: =IF(AND(ISNUMBER(L10),L10>0),"Valid","Review") | P10: =IF(OR(E10="",F10="",NOT(ISNUMBER(L10))),"Check Missing/Invalid Data","OK")
A11: PO-00413 | B11: 45662 | C11: Purchase Order | D11: SUP008 | E11: =IF(E11="","Unknown Supplier",TRIM(E11)) | F11: =IF(F11="","Unclassified",TRIM(F11)) | G11: Corrugated boxes | H11: Technology | I11: East | J11: 77 | K11: 151.88 | L11: 11695 | M11: Overdue | N11: =IF(OR(E11="Apex Office Supplies",E11="Apex Office Supply Ltd"),"Apex Office Supplies",IF(OR(E11="Northstar IT Services",E11="North Star IT Svc"),"Northstar IT Services",IF(OR(E11="Metro Logistics",E11="Metro Logistics Pvt Ltd"),"Metro Logistics",E11))) | O11: =IF(AND(ISNUMBER(L11),L11>0),"Valid","Review") | P11: =IF(OR(E11="",F11="",NOT(ISNUMBER(L11))),"Check Missing/Invalid Data","OK")
A12: PO-00117 | B12: 45662 | C12: Goods Receipt | D12: SUP010 | E12: =IF(E12="","Unknown Supplier",TRIM(E12)) | F12: =IF(F12="","Unclassified",TRIM(F12)) | G12: Natural gas | H12: Sales | I12: East | J12: 7 | K12: 2005.17 | L12: 14036.21 | M12: Paid | N12: =IF(OR(E12="Apex Office Supplies",E12="Apex Office Supply Ltd"),"Apex Office Supplies",IF(OR(E12="Northstar IT Services",E12="North Star IT Svc"),"Northstar IT Services",IF(OR(E12="Metro Logistics",E12="Metro Logistics Pvt Ltd"),"Metro Logistics",E12))) | O12: =IF(AND(ISNUMBER(L12),L12>0),"Valid","Review") | P12: =IF(OR(E12="",F12="",NOT(ISNUMBER(L12))),"Check Missing/Invalid Data","OK")
A13: PO-00331 | B13: 45662 | C13: Invoice | D13: SUP012 | E13: =IF(E13="","Unknown Supplier",TRIM(E13)) | F13: =IF(F13="","Unclassified",TRIM(F13)) | G13: Tools and supplies | H13: Operations | I13: West | J13: 111 | K13: 20.51 | L13: 2276.22 | M13: Paid | N13: =IF(OR(E13="Apex Office Supplies",E13="Apex Office Supply Ltd"),"Apex Office Supplies",IF(OR(E13="Northstar IT Services",E13="North Star IT Svc"),"Northstar IT Services",IF(OR(E13="Metro Logistics",E13="Metro Logistics Pvt Ltd"),"Metro Logistics",E13))) | O13: =IF(AND(ISNUMBER(L13),L13>0),"Valid","Review") | P13: =IF(OR(E13="",F13="",NOT(ISNUMBER(L13))),"Check Missing/Invalid Data","OK")
... A89: PO-00133 | B89: 45714 | C89: Purchase Order | D89: SUP011 | E89: =IF(E89="","Unknown Supplier",TRIM(E89)) | F89: =IF(F89="","Unclassified",TRIM(F89)) | G89: Promotional materials | H89: Technology | I89: North | J89: 46 | K89: 53.84 | L89: 2476.64 | M89: Paid | N89: =IF(OR(E89="Apex Office Supplies",E89="Apex Office Supply Ltd"),"Apex Office Supplies",IF(OR(E89="Northstar IT Services",E89="North Star IT Svc"),"Northstar IT Services",IF(OR(E89="Metro Logistics",E89="Metro Logistics Pvt Ltd"),"Metro Logistics",E89))) | O89: =IF(AND(ISNUMBER(L89),L89>0),"Valid","Review") | P89: =IF(OR(E89="",F89="",NOT(ISNUMBER(L89))),"Check Missing/Invalid Data","OK")
A90: PO-00252 | B90: 45715 | C90: Purchase Order | D90: SUP001 | E90: =IF(E90="","Unknown Supplier",TRIM(E90)) | F90: =IF(F90="","Unclassified",TRIM(F90)) | G90: Printer paper | H90: Operations | I90: North | J90: 99 | K90: 76.93 | M90: Paid | N90: =IF(OR(E90="Apex Office Supplies",E90="Apex Office Supply Ltd"),"Apex Office Supplies",IF(OR(E90="Northstar IT Services",E90="North Star IT Svc"),"Northstar IT Services",IF(OR(E90="Metro Logistics",E90="Metro Logistics Pvt Ltd"),"Metro Logistics",E90))) | O90: =IF(AND(ISNUMBER(L90),L90>0),"Valid","Review") | P90: =IF(OR(E90="",F90="",NOT(ISNUMBER(L90))),"Check Missing/Invalid Data","OK")
A91: PO-00447 | B91: 45715 | C91: Invoice | D91: SUP007 | E91: =IF(E91="","Unknown Supplier",TRIM(E91)) | F91: =IF(F91="","Unclassified",TRIM(F91)) | G91: Cleaning services | H91: Manufacturing | I91: South | J91: 84 | K91: 14.91 | L91: 1252.45 | M91: Overdue | N91: =IF(OR(E91="Apex Office Supplies",E91="Apex Office Supply Ltd"),"Apex Office Supplies",IF(OR(E91="Northstar IT Services",E91="North Star IT Svc"),"Northstar IT Services",IF(OR(E91="Metro Logistics",E91="Metro Logistics Pvt Ltd"),"Metro Logistics",E91))) | O91: =IF(AND(ISNUMBER(L91),L91>0),"Valid","Review") | P91: =IF(OR(E91="",F91="",NOT(ISNUMBER(L91))),"Check Missing/Invalid Data","OK")
A92: PO-00508 | B92: 45716 | C92: Purchase Order | D92: SUP008 | E92: =IF(E92="","Unknown Supplier",TRIM(E92)) | F92: =IF(F92="","Unclassified",TRIM(F92)) | G92: Labels | H92: Sales | I92: North | J92: 76 | K92: 114.27 | L92: 8684.9 | M92: Paid | N92: =IF(OR(E92="Apex Office Supplies",E92="Apex Office Supply Ltd"),"Apex Office Supplies",IF(OR(E92="Northstar IT Services",E92="North Star IT Svc"),"Northstar IT Services",IF(OR(E92="Metro Logistics",E92="Metro Logistics Pvt Ltd"),"Metro Logistics",E92))) | O92: =IF(AND(ISNUMBER(L92),L92>0),"Valid","Review") | P92: =IF(OR(E92="",F92="",NOT(ISNUMBER(L92))),"Check Missing/Invalid Data","OK")
A93: PO-00195 | B93: 45716 | C93: Goods Receipt | D93: SUP001 | E93: =IF(E93="","Unknown Supplier",TRIM(E93)) | F93: =IF(F93="","Unclassified",TRIM(F93)) | G93: Printer paper | H93: Technology | I93: East | J93: 50 | K93: 180.86 | L93: 9042.91 | M93: Overdue | N93: =IF(OR(E93="Apex Office Supplies",E93="Apex Office Supply Ltd"),"Apex Office Supplies",IF(OR(E93="Northstar IT Services",E93="North Star IT Svc"),"Northstar IT Services",IF(OR(E93="Metro Logistics",E93="Metro Logistics Pvt Ltd"),"Metro Logistics",E93))) | O93: =IF(AND(ISNUMBER(L93),L93>0),"Valid","Review") | P93: =IF(OR(E93="",F93="",NOT(ISNUMBER(L93))),"Check Missing/Invalid Data","OK")
A94: PO-00293 | B94: 45716 | C94: Goods Receipt | D94: SUP010 | E94: =IF(E94="","Unknown Supplier",TRIM(E94)) | F94: =IF(F94="","Unclassified",TRIM(F94)) | G94: Natural gas | H94: Corporate | I94: West | J94: 24 | K94: 747.96 | L94: 17951.1 | M94: Overdue | N94: =IF(OR(E94="Apex Office Supplies",E94="Apex Office Supply Ltd"),"Apex Office Supplies",IF(OR(E94="Northstar IT Services",E94="North Star IT Svc"),"Northstar IT Services",IF(OR(E94="Metro Logistics",E94="Metro Logistics Pvt Ltd"),"Metro Logistics",E94))) | O94: =IF(AND(ISNUMBER(L94),L94>0),"Valid","Review") | P94: =IF(OR(E94="",F94="",NOT(ISNUMBER(L94))),"Check Missing/Invalid Data","OK")
A95: PO-00478 | B95: 45716 | C95: Goods Receipt | D95: SUP007 | E95: =IF(E95="","Unknown Supplier",TRIM(E95)) | F95: =IF(F95="","Unclassified",TRIM(F95)) | G95: Facility maintenance | H95: Manufacturing | I95: West | J95: 4 | K95: 3266.17 | L95: 13064.68 | M95: Pending | N95: =IF(OR(E95="Apex Office Supplies",E95="Apex Office Supply Ltd"),"Apex Office Supplies",IF(OR(E95="Northstar IT Services",E95="North Star IT Svc"),"Northstar IT Services",IF(OR(E95="Metro Logistics",E95="Metro Logistics Pvt Ltd"),"Metro Logistics",E95))) | O95: =IF(AND(ISNUMBER(L95),L95>0),"Valid","Review") | P95: =IF(OR(E95="",F95="",NOT(ISNUMBER(L95))),"Check Missing/Invalid Data","OK")
A96: PO-00435 | B96: 45717 | C96: Invoice | D96: SUP007 | E96: =IF(E96="","Unknown Supplier",TRIM(E96)) | F96: =IF(F96="","Unclassified",TRIM(F96)) | G96: Security services | H96: Operations | I96: South | J96: 33 | K96: 70.6 | L96: 2329.88 | M96: Overdue | N96: =IF(OR(E96="Apex Office Supplies",E96="Apex Office Supply Ltd"),"Apex Office Supplies",IF(OR(E96="Northstar IT Services",E96="North Star IT Svc"),"Northstar IT Services",IF(OR(E96="Metro Logistics",E96="Metro Logistics Pvt Ltd"),"Metro Logistics",E96))) | O96: =IF(AND(ISNUMBER(L96),L96>0),"Valid","Review") | P96: =IF(OR(E96="",F96="",NOT(ISNUMBER(L96))),"Check Missing/Invalid Data","OK")
A97: PO-00442 | B97: 45717 | C97: Purchase Order | D97: SUP002 | E97: =IF(E97="","Unknown Supplier",TRIM(E97)) | F97: =IF(F97="","Unclassified",TRIM(F97)) | G97: Toner cartridges | H97: Operations | I97: East | J97: 2 | K97: 8019.21 | L97: 16038.42 | M97: Pending | N97: =IF(OR(E97="Apex Office Supplies",E97="Apex Office Supply Ltd"),"Apex Office Supplies",IF(OR(E97="Northstar IT Services",E97="North Star IT Svc"),"Northstar IT Services",IF(OR(E97="Metro Logistics",E97="Metro Logistics Pvt Ltd"),"Metro Logistics",E97))) | O97: =IF(AND(ISNUMBER(L97),L97>0),"Valid","Review") | P97: =IF(OR(E97="",F97="",NOT(ISNUMBER(L97))),"Check Missing/Invalid Data","OK")
A98: PO-00531 | B98: 45717 | C98: Goods Receipt | D98: SUP009 | E98: =IF(E98="","Unknown Supplier",TRIM(E98)) | F98: =IF(F98="","Unclassified",TRIM(F98)) | G98: Training services | H98: Sales | I98: West | J98: 105 | K98: 255.57 | L98: 26834.33 | M98: Overdue | N98: =IF(OR(E98="Apex Office Supplies",E98="Apex Office Supply Ltd"),"Apex Office Supplies",IF(OR(E98="Northstar IT Services",E98="North Star IT Svc"),"Northstar IT Services",IF(OR(E98="Metro Logistics",E98="Metro Logistics Pvt Ltd"),"Metro Logistics",E98))) | O98: =IF(AND(ISNUMBER(L98),L98>0),"Valid","Review") | P98: =IF(OR(E98="",F98="",NOT(ISNUMBER(L98))),"Check Missing/Invalid Data","OK")
A99: PO-00533 | B99: 45717 | C99: Invoice | D99: SUP005 | E99: =IF(E99="","Unknown Supplier",TRIM(E99)) | F99: =IF(F99="","Unclassified",TRIM(F99)) | G99: Facility maintenance | H99: Technology | I99: North | J99: 30 | K99: 407.44 | L99: 12223.2 | M99: Overdue | N99: =IF(OR(E99="Apex Office Supplies",E99="Apex Office Supply Ltd"),"Apex Office Supplies",IF(OR(E99="Northstar IT Services",E99="North Star IT Svc"),"Northstar IT Services",IF(OR(E99="Metro Logistics",E99="Metro Logistics Pvt Ltd"),"Metro Logistics",E99))) | O99: =IF(AND(ISNUMBER(L99),L99>0),"Valid","Review") | P99: =IF(OR(E99="",F99="",NOT(ISNUMBER(L99))),"Check Missing/Invalid Data","OK")
A100: PO-00424 | B100: 45718 | C100: Goods Receipt | D100: SUP008 | E100: =IF(E100="","Unknown Supplier",TRIM(E100)) | F100: =IF(F100="","Unclassified",TRIM(F100)) | G100: Software support | H100: Sales | I100: East | J100: 25 | K100: 582.3 | L100: 14557.59 | M100: Pending | N100: =IF(OR(E100="Apex Office Supplies",E100="Apex Office Supply Ltd"),"Apex Office Supplies",IF(OR(E100="Northstar IT Services",E100="North Star IT Svc"),"Northstar IT Services",IF(OR(E100="Metro Logistics",E100="Metro Logistics Pvt Ltd"),"Metro Logistics",E100))) | O100: =IF(AND(ISNUMBER(L100),L100>0),"Valid","Review") | P100: =IF(OR(E100="",F100="",NOT(ISNUMBER(L100))),"Check Missing/Invalid Data","OK")
A101: PO-00522 | B101: 45718 | C101: Purchase Order | D101: SUP012 | E101: =IF(E101="","Unknown Supplier",TRIM(E101)) | F101: =IF(F101="","Unclassified",TRIM(F101)) | G101: Repair parts | H101: Manufacturing | I101: West | J101: 21 | K101: 672.48 | L101: 14121.99 | M101: Pending | N101: =IF(OR(E101="Apex Office Supplies",E101="Apex Office Supply Ltd"),"Apex Office Supplies",IF(OR(E101="Northstar IT Services",E101="North Star IT Svc"),"Northstar IT Services",IF(OR(E101="Metro Logistics",E101="Metro Logistics Pvt Ltd"),"Metro Logistics",E101))) | O101: =IF(AND(ISNUMBER(L101),L101>0),"Valid","Review") | P101: =IF(OR(E101="",F101="",NOT(ISNUMBER(L101))),"Check Missing/Invalid Data","OK")
A102: PO-00361 | B102: 45719 | C102: Goods Receipt | D102: SUP002 | E102: =IF(E102="","Unknown Supplier",TRIM(E102)) | F102: =IF(F102="","Unclassified",TRIM(F102)) | G102: Toner cartridges | H102: Manufacturing | I102: North | J102: 106 | K102: 116.86 | L102: 12386.66 | M102: Paid | N102: =IF(OR(E102="Apex Office Supplies",E102="Apex Office Supply Ltd"),"Apex Office Supplies",IF(OR(E102="Northstar IT Services",E102="North Star IT Svc"),"Northstar IT Services",IF(OR(E102="Metro Logistics",E102="Metro Logistics Pvt Ltd"),"Metro Logistics",E102))) | O102: =IF(AND(ISNUMBER(L102),L102>0),"Valid","Review") | P102: =IF(OR(E102="",F102="",NOT(ISNUMBER(L102))),"Check Missing/Invalid Data","OK")
... A279: PO-00170 | B279: 45830 | C279: Purchase Order | D279: SUP010 | E279: =IF(E279="","Unknown Supplier",TRIM(E279)) | F279: =IF(F279="","Unclassified",TRIM(F279)) | G279: Natural gas | H279: Manufacturing | I279: South | J279: 21 | K279: 326.46 | L279: 6855.75 | M279: Overdue | N279: =IF(OR(E279="Apex Office Supplies",E279="Apex Office Supply Ltd"),"Apex Office Supplies",IF(OR(E279="Northstar IT Services",E279="North Star IT Svc"),"Northstar IT Services",IF(OR(E279="Metro Logistics",E279="Metro Logistics Pvt Ltd"),"Metro Logistics",E279))) | O279: =IF(AND(ISNUMBER(L279),L279>0),"Valid","Review") | P279: =IF(OR(E279="",F279="",NOT(ISNUMBER(L279))),"Check Missing/Invalid Data","OK")
A280: PO-00025 | B280: 45831 | C280: Purchase Order | D280: SUP002 | E280: =IF(E280="","Unknown Supplier",TRIM(E280)) | F280: =IF(F280="","Unclassified",TRIM(F280)) | G280: Pens and stationery | H280: Operations | I280: East | J280: 58 | K280: 60.71 | M280: Pending | N280: =IF(OR(E280="Apex Office Supplies",E280="Apex Office Supply Ltd"),"Apex Office Supplies",IF(OR(E280="Northstar IT Services",E280="North Star IT Svc"),"Northstar IT Services",IF(OR(E280="Metro Logistics",E280="Metro Logistics Pvt Ltd"),"Metro Logistics",E280))) | O280: =IF(AND(ISNUMBER(L280),L280>0),"Valid","Review") | P280: =IF(OR(E280="",F280="",NOT(ISNUMBER(L280))),"Check Missing/Invalid Data","OK")
A281: PO-00448 | B281: 45831 | C281: Invoice | D281: SUP009 | E281: =IF(E281="","Unknown Supplier",TRIM(E281)) | F281: =IF(F281="","Unclassified",TRIM(F281)) | G281: Audit support | H281: Operations | I281: West | J281: 13 | K281: 1653.76 | L281: 21498.84 | M281: Pending | N281: =IF(OR(E281="Apex Office Supplies",E281="Apex Office Supply Ltd"),"Apex Office Supplies",IF(OR(E281="Northstar IT Services",E281="North Star IT Svc"),"Northstar IT Services",IF(OR(E281="Metro Logistics",E281="Metro Logistics Pvt Ltd"),"Metro Logistics",E281))) | O281: =IF(AND(ISNUMBER(L281),L281>0),"Valid","Review") | P281: =IF(OR(E281="",F281="",NOT(ISNUMBER(L281))),"Check Missing/Invalid Data","OK")
A282: PO-00458 | B282: 45831 | C282: Goods Receipt | D282: SUP002 | E282: =IF(E282="","Unknown Supplier",TRIM(E282)) | F282: =IF(F282="","Unclassified",TRIM(F282)) | G282: Toner cartridges | H282: Corporate | I282: West | J282: 82 | K282: 11.6 | L282: 951.43 | M282: Pending | N282: =IF(OR(E282="Apex Office Supplies",E282="Apex Office Supply Ltd"),"Apex Office Supplies",IF(OR(E282="Northstar IT Services",E282="North Star IT Svc"),"Northstar IT Services",IF(OR(E282="Metro Logistics",E282="Metro Logistics Pvt Ltd"),"Metro Logistics",E282))) | O282: =IF(AND(ISNUMBER(L282),L282>0),"Valid","Review") | P282: =IF(OR(E282="",F282="",NOT(ISNUMBER(L282))),"Check Missing/Invalid Data","OK")
A283: PO-00209 | B283: 45832 | C283: Goods Receipt | D283: SUP010 | E283: =IF(E283="","Unknown Supplier",TRIM(E283)) | F283: =IF(F283="","Unclassified",TRIM(F283)) | G283: Water services | H283: Sales | I283: South | J283: 41 | K283: 378.62 | L283: 15523.35 | M283: Pending | N283: =IF(OR(E283="Apex Office Supplies",E283="Apex Office Supply Ltd"),"Apex Office Supplies",IF(OR(E283="Northstar IT Services",E283="North Star IT Svc"),"Northstar IT Services",IF(OR(E283="Metro Logistics",E283="Metro Logistics Pvt Ltd"),"Metro Logistics",E283))) | O283: =IF(AND(ISNUMBER(L283),L283>0),"Valid","Review") | P283: =IF(OR(E283="",F283="",NOT(ISNUMBER(L283))),"Check Missing/Invalid Data","OK")
A284: PO-00015 | B284: 45832 | C284: Goods Receipt | D284: SUP002 | E284: =IF(E284="","Unknown Supplier",TRIM(E284)) | F284: =IF(F284="","Unclassified",TRIM(F284)) | G284: Toner cartridges | H284: Technology | I284: South | J284: 1 | K284: 2947.86 | L284: 2947.86 | M284: Overdue | N284: =IF(OR(E284="Apex Office Supplies",E284="Apex Office Supply Ltd"),"Apex Office Supplies",IF(OR(E284="Northstar IT Services",E284="North Star IT Svc"),"Northstar IT Services",IF(OR(E284="Metro Logistics",E284="Metro Logistics Pvt Ltd"),"Metro Logistics",E284))) | O284: =IF(AND(ISNUMBER(L284),L284>0),"Valid","Review") | P284: =IF(OR(E284="",F284="",NOT(ISNUMBER(L284))),"Check Missing/Invalid Data","OK")
A285: PO-00464 | B285: 45834 | C285: Goods Receipt | D285: SUP011 | E285: =IF(E285="","Unknown Supplier",TRIM(E285)) | F285: =IF(F285="","Unclassified",TRIM(F285)) | G285: Promotional materials | H285: Technology | I285: North | J285: 23 | K285: 557.47 | L285: 12821.89 | M285: Pending | N285: =IF(OR(E285="Apex Office Supplies",E285="Apex Office Supply Ltd"),"Apex Office Supplies",IF(OR(E285="Northstar IT Services",E285="North Star IT Svc"),"Northstar IT Services",IF(OR(E285="Metro Logistics",E285="Metro Logistics Pvt Ltd"),"Metro Logistics",E285))) | O285: =IF(AND(ISNUMBER(L285),L285>0),"Valid","Review") | P285: =IF(OR(E285="",F285="",NOT(ISNUMBER(L285))),"Check Missing/Invalid Data","OK")
A286: PO-00540 | B286: 45835 | C286: Purchase Order | D286: SUP007 | E286: =IF(E286="","Unknown Supplier",TRIM(E286)) | F286: =IF(F286="","Unclassified",TRIM(F286)) | G286: Security services | H286: Manufacturing | I286: West | J286: 59 | K286: 237.17 | L286: 13993.16 | M286: Pending | N286: =IF(OR(E286="Apex Office Supplies",E286="Apex Office Supply Ltd"),"Apex Office Supplies",IF(OR(E286="Northstar IT Services",E286="North Star IT Svc"),"Northstar IT Services",IF(OR(E286="Metro Logistics",E286="Metro Logistics Pvt Ltd"),"Metro Logistics",E286))) | O286: =IF(AND(ISNUMBER(L286),L286>0),"Valid","Review") | P286: =IF(OR(E286="",F286="",NOT(ISNUMBER(L286))),"Check Missing/Invalid Data","OK")
A287: PO-00477 | B287: 45835 | C287: Goods Receipt | D287: SUP008 | E287: =IF(E287="","Unknown Supplier",TRIM(E287)) | F287: =IF(F287="","Unclassified",TRIM(F287)) | G287: Corrugated boxes | H287: Corporate | I287: East | J287: 118 | K287: 98.34 | L287: 11603.69 | M287: Pending | N287: =IF(OR(E287="Apex Office Supplies",E287="Apex Office Supply Ltd"),"Apex Office Supplies",IF(OR(E287="Northstar IT Services",E287="North Star IT Svc"),"Northstar IT Services",IF(OR(E287="Metro Logistics",E287="Metro Logistics Pvt Ltd"),"Metro Logistics",E287))) | O287: =IF(AND(ISNUMBER(L287),L287>0),"Valid","Review") | P287: =IF(OR(E287="",F287="",NOT(ISNUMBER(L287))),"Check Missing/Invalid Data","OK")
A288: PO-00095 | B288: 45836 | C288: Purchase Order | D288: SUP007 | E288: =IF(E288="","Unknown Supplier",TRIM(E288)) | F288: =IF(F288="","Unclassified",TRIM(F288)) | G288: Facility maintenance | H288: Sales | I288: West | J288: 110 | K288: 110.02 | L288: 12101.99 | M288: Pending | N288: =IF(OR(E288="Apex Office Supplies",E288="Apex Office Supply Ltd"),"Apex Office Supplies",IF(OR(E288="Northstar IT Services",E288="North Star IT Svc"),"Northstar IT Services",IF(OR(E288="Metro Logistics",E288="Metro Logistics Pvt Ltd"),"Metro Logistics",E288))) | O288: =IF(AND(ISNUMBER(L288),L288>0),"Valid","Review") | P288: =IF(OR(E288="",F288="",NOT(ISNUMBER(L288))),"Check Missing/Invalid Data","OK")
A289: PO-00549 | B289: 45837 | C289: Goods Receipt | D289: SUP011 | E289: =IF(E289="","Unknown Supplier",TRIM(E289)) | F289: =IF(F289="","Unclassified",TRIM(F289)) | G289: Promotional materials | H289: Manufacturing | I289: South | J289: 74 | K289: 49.69 | L289: 3677.37 | M289: Pending | N289: =IF(OR(E289="Apex Office Supplies",E289="Apex Office Supply Ltd"),"Apex Office Supplies",IF(OR(E289="Northstar IT Services",E289="North Star IT Svc"),"Northstar IT Services",IF(OR(E289="Metro Logistics",E289="Metro Logistics Pvt Ltd"),"Metro Logistics",E289))) | O289: =IF(AND(ISNUMBER(L289),L289>0),"Valid","Review") | P289: =IF(OR(E289="",F289="",NOT(ISNUMBER(L289))),"Check Missing/Invalid Data","OK")
A290: PO-00334 | B290: 45837 | C290: Invoice | D290: SUP012 | E290: =IF(E290="","Unknown Supplier",TRIM(E290)) | F290: =IF(F290="","Unclassified",TRIM(F290)) | G290: Tools and supplies | H290: Sales | I290: South | J290: 118 | K290: 114.4 | L290: 13499.05 | M290: Paid | N290: =IF(OR(E290="Apex Office Supplies",E290="Apex Office Supply Ltd"),"Apex Office Supplies",IF(OR(E290="Northstar IT Services",E290="North Star IT Svc"),"Northstar IT Services",IF(OR(E290="Metro Logistics",E290="Metro Logistics Pvt Ltd"),"Metro Logistics",E290))) | O290: =IF(AND(ISNUMBER(L290),L290>0),"Valid","Review") | P290: =IF(OR(E290="",F290="",NOT(ISNUMBER(L290))),"Check Missing/Invalid Data","OK")
A291: PO-00191 | B291: 45838 | C291: Purchase Order | D291: SUP010 | E291: =IF(E291="","Unknown Supplier",TRIM(E291)) | F291: =IF(F291="","Unclassified",TRIM(F291)) | G291: Electricity | H291: Sales | I291: East | J291: 102 | K291: 49.3 | L291: 5029.05 | M291: Overdue | N291: =IF(OR(E291="Apex Office Supplies",E291="Apex Office Supply Ltd"),"Apex Office Supplies",IF(OR(E291="Northstar IT Services",E291="North Star IT Svc"),"Northstar IT Services",IF(OR(E291="Metro Logistics",E291="Metro Logistics Pvt Ltd"),"Metro Logistics",E291))) | O291: =IF(AND(ISNUMBER(L291),L291>0),"Valid","Review") | P291: =IF(OR(E291="",F291="",NOT(ISNUMBER(L291))),"Check Missing/Invalid Data","OK")
...

Sheet Supplier_Review
A1: Normalized Supplier | B1: Total Spend (USD) | C1: Transaction Count | D1: Supplier Concentration
A2: Apex Office Supplies | B2: =SUMIF(Clean_Data!$N:$N,A2,Clean_Data!$L:$L) | C2: =COUNTIF(Clean_Data!$N:$N,A2) | D2: =IFERROR(B2/SUM($B$2:$B$11),0)
A3: Northstar IT Services | B3: =SUMIF(Clean_Data!$N:$N,A3,Clean_Data!$L:$L) | C3: =COUNTIF(Clean_Data!$N:$N,A3) | D3: =IFERROR(B3/SUM($B$2:$B$11),0)
A4: Metro Logistics | B4: =SUMIF(Clean_Data!$N:$N,A4,Clean_Data!$L:$L) | C4: =COUNTIF(Clean_Data!$N:$N,A4) | D4: =IFERROR(B4/SUM($B$2:$B$11),0)
A5: BrightClean Facilities | B5: =SUMIF(Clean_Data!$N:$N,A5,Clean_Data!$L:$L) | C5: =COUNTIF(Clean_Data!$N:$N,A5) | D5: =IFERROR(B5/SUM($B$2:$B$11),0)
A6: GreenLeaf Packaging | B6: =SUMIF(Clean_Data!$N:$N,A6,Clean_Data!$L:$L) | C6: =COUNTIF(Clean_Data!$N:$N,A6) | D6: =IFERROR(B6/SUM($B$2:$B$11),0)
A7: Summit Consulting | B7: =SUMIF(Clean_Data!$N:$N,A7,Clean_Data!$L:$L) | C7: =COUNTIF(Clean_Data!$N:$N,A7) | D7: =IFERROR(B7/SUM($B$2:$B$11),0)
A8: Urban Energy Solutions | B8: =SUMIF(Clean_Data!$N:$N,A8,Clean_Data!$L:$L) | C8: =COUNTIF(Clean_Data!$N:$N,A8) | D8: =IFERROR(B8/SUM($B$2:$B$11),0)
A9: Vertex Marketing | B9: =SUMIF(Clean_Data!$N:$N,A9,Clean_Data!$L:$L) | C9: =COUNTIF(Clean_Data!$N:$N,A9) | D9: =IFERROR(B9/SUM($B$2:$B$11),0)
A10: Pioneer Hardware | B10: =SUMIF(Clean_Data!$N:$N,A10,Clean_Data!$L:$L) | C10: =COUNTIF(Clean_Data!$N:$N,A10) | D10: =IFERROR(B10/SUM($B$2:$B$11),0)
A11: Unknown Supplier | B11: =SUMIF(Clean_Data!$N:$N,A11,Clean_Data!$L:$L) | C11: =COUNTIF(Clean_Data!$N:$N,A11) | D11: =IFERROR(B11/SUM($B$2:$B$11),0)

Sheet Category_Summary
A1: Category | B1: Total Spend (USD) | C1: Transaction Count | D1: Spend Share
A2: Office Supplies | B2: =SUMIF(Clean_Data!$F:$F,A2,Clean_Data!$L:$L) | C2: =COUNTIF(Clean_Data!$F:$F,A2) | D2: =IFERROR(B2/SUM($B$2:$B$10),0)
A3: IT Services | B3: =SUMIF(Clean_Data!$F:$F,A3,Clean_Data!$L:$L) | C3: =COUNTIF(Clean_Data!$F:$F,A3) | D3: =IFERROR(B3/SUM($B$2:$B$10),0)
A4: Logistics | B4: =SUMIF(Clean_Data!$F:$F,A4,Clean_Data!$L:$L) | C4: =COUNTIF(Clean_Data!$F:$F,A4) | D4: =IFERROR(B4/SUM($B$2:$B$10),0)
A5: Facilities | B5: =SUMIF(Clean_Data!$F:$F,A5,Clean_Data!$L:$L) | C5: =COUNTIF(Clean_Data!$F:$F,A5) | D5: =IFERROR(B5/SUM($B$2:$B$10),0)
A6: Packaging | B6: =SUMIF(Clean_Data!$F:$F,A6,Clean_Data!$L:$L) | C6: =COUNTIF(Clean_Data!$F:$F,A6) | D6: =IFERROR(B6/SUM($B$2:$B$10),0)
A7: Professional Services | B7: =SUMIF(Clean_Data!$F:$F,A7,Clean_Data!$L:$L) | C7: =COUNTIF(Clean_Data!$F:$F,A7) | D7: =IFERROR(B7/SUM($B$2:$B$10),0)
A8: Utilities | B8: =SUMIF(Clean_Data!$F:$F,A8,Clean_Data!$L:$L) | C8: =COUNTIF(Clean_Data!$F:$F,A8) | D8: =IFERROR(B8/SUM($B$2:$B$10),0)
A9: Marketing | B9: =SUMIF(Clean_Data!$F:$F,A9,Clean_Data!$L:$L) | C9: =COUNTIF(Clean_Data!$F:$F,A9) | D9: =IFERROR(B9/SUM($B$2:$B$10),0)
A10: Maintenance | B10: =SUMIF(Clean_Data!$F:$F,A10,Clean_Data!$L:$L) | C10: =COUNTIF(Clean_Data!$F:$F,A10) | D10: =IFERROR(B10/SUM($B$2:$B$10),0)

Sheet Monthly_Summary
A1: Month | B1: Total Spend (USD) | C1: Transaction Count
A2: 45658 | B2: =SUMIFS(Clean_Data!$L:$L,Clean_Data!$B:$B,">="&A2,Clean_Data!$B:$B,"<"&EDATE(A2,1)) | C2: =COUNTIFS(Clean_Data!$B:$B,">="&A2,Clean_Data!$B:$B,"<"&EDATE(A2,1))
A3: 45689 | B3: =SUMIFS(Clean_Data!$L:$L,Clean_Data!$B:$B,">="&A3,Clean_Data!$B:$B,"<"&EDATE(A3,1)) | C3: =COUNTIFS(Clean_Data!$B:$B,">="&A3,Clean_Data!$B:$B,"<"&EDATE(A3,1))
A4: 45717 | B4: =SUMIFS(Clean_Data!$L:$L,Clean_Data!$B:$B,">="&A4,Clean_Data!$B:$B,"<"&EDATE(A4,1)) | C4: =COUNTIFS(Clean_Data!$B:$B,">="&A4,Clean_Data!$B:$B,"<"&EDATE(A4,1))
A5: 45748 | B5: =SUMIFS(Clean_Data!$L:$L,Clean_Data!$B:$B,">="&A5,Clean_Data!$B:$B,"<"&EDATE(A5,1)) | C5: =COUNTIFS(Clean_Data!$B:$B,">="&A5,Clean_Data!$B:$B,"<"&EDATE(A5,1))
A6: 45778 | B6: =SUMIFS(Clean_Data!$L:$L,Clean_Data!$B:$B,">="&A6,Clean_Data!$B:$B,"<"&EDATE(A6,1)) | C6: =COUNTIFS(Clean_Data!$B:$B,">="&A6,Clean_Data!$B:$B,"<"&EDATE(A6,1))
A7: 45809 | B7: =SUMIFS(Clean_Data!$L:$L,Clean_Data!$B:$B,">="&A7,Clean_Data!$B:$B,"<"&EDATE(A7,1)) | C7: =COUNTIFS(Clean_Data!$B:$B,">="&A7,Clean_Data!$B:$B,"<"&EDATE(A7,1))
A8: 45839 | B8: =SUMIFS(Clean_Data!$L:$L,Clean_Data!$B:$B,">="&A8,Clean_Data!$B:$B,"<"&EDATE(A8,1)) | C8: =COUNTIFS(Clean_Data!$B:$B,">="&A8,Clean_Data!$B:$B,"<"&EDATE(A8,1))
A9: 45870 | B9: =SUMIFS(Clean_Data!$L:$L,Clean_Data!$B:$B,">="&A9,Clean_Data!$B:$B,"<"&EDATE(A9,1)) | C9: =COUNTIFS(Clean_Data!$B:$B,">="&A9,Clean_Data!$B:$B,"<"&EDATE(A9,1))
A10: 45901 | B10: =SUMIFS(Clean_Data!$L:$L,Clean_Data!$B:$B,">="&A10,Clean_Data!$B:$B,"<"&EDATE(A10,1)) | C10: =COUNTIFS(Clean_Data!$B:$B,">="&A10,Clean_Data!$B:$B,"<"&EDATE(A10,1))
A11: 45931 | B11: =SUMIFS(Clean_Data!$L:$L,Clean_Data!$B:$B,">="&A11,Clean_Data!$B:$B,"<"&EDATE(A11,1)) | C11: =COUNTIFS(Clean_Data!$B:$B,">="&A11,Clean_Data!$B:$B,"<"&EDATE(A11,1))
A12: 45962 | B12: =SUMIFS(Clean_Data!$L:$L,Clean_Data!$B:$B,">="&A12,Clean_Data!$B:$B,"<"&EDATE(A12,1)) | C12: =COUNTIFS(Clean_Data!$B:$B,">="&A12,Clean_Data!$B:$B,"<"&EDATE(A12,1))
A13: 45992 | B13: =SUMIFS(Clean_Data!$L:$L,Clean_Data!$B:$B,">="&A13,Clean_Data!$B:$B,"<"&EDATE(A13,1)) | C13: =COUNTIFS(Clean_Data!$B:$B,">="&A13,Clean_Data!$B:$B,"<"&EDATE(A13,1))
